Workbook
Name Slicer_DoctorID: #N/A
Name Slicer_ResourceType: #N/A

Sheet feedback_data
A1: FeedbackID | B1: PatientID | C1: Department | D1: Feedback Score | E1: Comments | F1: WaitTime( in min) | G1: =VLOOKUP(A2, CHOOSE({1,2}, appointment_data!A:A, appointment_data!C:C), 2, FALSE) -> #N/A
A2: F1000 | B2: P96099 | C2: Cardiology | D2: 4 | E2: Delayed response | F2: 45 | G2: =VLOOKUP(TRIM(B2), appointment_data!A:Z, 2, FALSE) -> N/A
A3: F1001 | B3: P16262 | C3: Orthopedics | D3: 3 | E3: Needs improvement | F3: 45 | G3: =VLOOKUP(TRIM(B4), appointment_data!A:Z, 2, FALSE) -> A7537
A4: F1002 | B4: P99601 | C4: N/A | D4: 6.2849741 | E4: Excellent care | F4: 30 | G4: =VLOOKUP(TRIM(B5), appointment_data!A:Z, 2, FALSE) -> A8866
A5: F1003 | B5: P55235 | C5: Neurology | D5: 9 | E5: Amazing team | F5: 30 | G5: =VLOOKUP(TRIM(B6), appointment_data!A:Z, 2, FALSE) -> A3039
A6: F1004 | B6: P93372 | C6: Pediatric | D6: 8 | E6: Great doctors | F6: 45 | G6: =VLOOKUP(TRIM(B7), appointment_data!A:Z, 2, FALSE) -> A3237
A7: F1005 | B7: P84444 | C7: Pediatric | D7: 5 | E7: Satisfactory | F7: 45 | G7: =VLOOKUP(TRIM(B8), appointment_data!A:Z, 2, FALSE) -> A8127
A8: F1006 | B8: P41013 | C8: Neurology | D8: 4 | E8: Delayed response | F8: 45 | G8: =VLOOKUP(TRIM(B9), appointment_data!A:Z, 2, FALSE) -> A7025
A9: F1007 | B9: P17235 | C9: Neurology | D9: 7 | E9: Child-friendly staff | F9: 45 | G9: =VLOOKUP(TRIM(B10), appointment_data!A:Z, 2, FALSE) -> A8462
A10: F1008 | B10: P35768 | C10: Cardiology | D10: 7 | E10: Child-friendly staff | F10: 45 | G10: =VLOOKUP(TRIM(B11), appointment_data!A:Z, 2, FALSE) -> A9018
A11: F1009 | B11: P28832 | C11: Orthopedics | D11: 4 | E11: Delayed response | F11: 45 | G11: =VLOOKUP(TRIM(B12), appointment_data!A:Z, 2, FALSE) -> A7791
A12: F1010 | B12: P29680 | C12: Orthopedics | D12: 4 | E12: Room cleanliness issue | F12: 45 | G12: =VLOOKUP(TRIM(B13), appointment_data!A:Z, 2, FALSE) -> A4362
A13: F1011 | B13: P93978 | C13: Orthopedics | D13: 3 | E13: Long wait times | F13: 45 | G13: =VLOOKUP(TRIM(B14), appointment_data!A:Z, 2, FALSE) -> N/A
A14: F1012 | B14: P83760 | C14: Pediatric | D14: 7 | E14: Child-friendly staff | F14: 45 | G14: =VLOOKUP(TRIM(B15), appointment_data!A:Z, 2, FALSE) -> A1132
... A200: F1199 | B200: P13204 | C200: Cardiology | D200: 5 | E200: Average | F200: 45 | G200: =VLOOKUP(TRIM(B201), appointment_data!A:Z, 2, FALSE) -> #N/A

Sheet combined_dataset
A1: PatientID | B1: Date | C1: Time | D1: Department | E1: Feedback Score | F1: Comments | G1: WaitTime( in min) | H1: Satisfaction Level
A2: P96099 | B2: =VLOOKUP(A2, appointment_data!A:G, 5, FALSE) -> 45292 | C2: =VLOOKUP(A2, appointment_data!A:G, 6, FALSE) -> N/A | D2: Cardiology | E2: 4 | F2: Delayed response | G2: 45 | H2: =IF(E2>=4, "High", "Low") -> High
A3: P16262 | B3: =VLOOKUP(A3, appointment_data!A:G, 5, FALSE) -> 45545 | C3: =VLOOKUP(A3, appointment_data!A:G, 6, FALSE) -> 0.54166667 | D3: Orthopedics | E3: 3 | F3: Needs improvement | G3: 45 | H3: =IF(E3>=4, "High", "Low") -> Low
A4: P99601 | B4: =VLOOKUP(A4, appointment_data!A:G, 5, FALSE) -> 45643 | C4: =VLOOKUP(A4, appointment_data!A:G, 6, FALSE) -> 0.625 | D4: N/A | E4: 6.2849741 | F4: Excellent care | G4: 30 | H4: =IF(E4>=4, "High", "Low") -> High
A5: P55235 | B5: =VLOOKUP(A5, appointment_data!A:G, 5, FALSE) -> 45482 | C5: =VLOOKUP(A5, appointment_data!A:G, 6, FALSE) -> 0.64583333 | D5: Neurology | E5: 9 | F5: Amazing team | G5: 30 | H5: =IF(E5>=4, "High", "Low") -> High
A6: P93372 | B6: =VLOOKUP(A6, appointment_data!A:G, 5, FALSE) -> 45516 | C6: =VLOOKUP(A6, appointment_data!A:G, 6, FALSE) -> 0.75 | D6: Pediatric | E6: 8 | F6: Great doctors | G6: 45 | H6: =IF(E6>=4, "High", "Low") -> High
A7: P84444 | B7: =VLOOKUP(A7, appointment_data!A:G, 5, FALSE) -> 45357 | C7: =VLOOKUP(A7, appointment_data!A:G, 6, FALSE) -> 0.72916667 | D7: Pediatric | E7: 5 | F7: Satisfactory | G7: 45 | H7: =IF(E7>=4, "High", "Low") -> High
A8: P41013 | B8: =VLOOKUP(A8, appointment_data!A:G, 5, FALSE) -> 45383 | C8: =VLOOKUP(A8, appointment_data!A:G, 6, FALSE) -> 0.45833333 | D8: Neurology | E8: 4 | F8: Delayed response | G8: 45 | H8: =IF(E8>=4, "High", "Low") -> High
A9: P17235 | B9: =VLOOKUP(A9, appointment_data!A:G, 5, FALSE) -> 45581 | C9: =VLOOKUP(A9, appointment_data!A:G, 6, FALSE) -> 0.625 | D9: Neurology | E9: 7 | F9: Child-friendly staff | G9: 45 | H9: =IF(E9>=4, "High", "Low") -> High
A10: P35768 | B10: =VLOOKUP(A10, appointment_data!A:G, 5, FALSE) -> 45558 | C10: =VLOOKUP(A10, appointment_data!A:G, 6, FALSE) -> 0.64583333 | D10: Cardiology | E10: 7 | F10: Child-friendly staff | G10: 45 | H10: =IF(E10>=4, "High", "Low") -> High
A11: P28832 | B11: =VLOOKUP(A11, appointment_data!A:G, 5, FALSE) -> 45395 | C11: =VLOOKUP(A11, appointment_data!A:G, 6, FALSE) -> 0.5625 | D11: Orthopedics | E11: 4 | F11: Delayed response | G11: 45 | H11: =IF(E11>=4, "High", "Low") -> High
A12: P29680 | B12: =VLOOKUP(A12, appointment_data!A:G, 5, FALSE) -> 45460 | C12: =VLOOKUP(A12, appointment_data!A:G, 6, FALSE) -> 0.35416667 | D12: Orthopedics | E12: 4 | F12: Room cleanliness issue | G12: 45 | H12: =IF(E12>=4, "High", "Low") -> High
A13: P93978 | B13: =VLOOKUP(A13, appointment_data!A:G, 5, FALSE) -> 45519 | C13: =VLOOKUP(A13, appointment_data!A:G, 6, FALSE) -> 0.64583333 | D13: Orthopedics | E13: 3 | F13: Long wait times | G13: 45 | H13: =IF(E13>=4, "High", "Low") -> Low
... A200: P13204 | B200: =VLOOKUP(A200, appointment_data!A:G, 5, FALSE) -> 45568 | C200: =VLOOKUP(A200, appointment_data!A:G, 6, FALSE) -> 0.47916667 | D200: Cardiology | E200: 5 | F200: Average | G200: 45 | H200: =IF(E200>=4, "High", "Low") -> High

Sheet appointment_data
A1: PatientID | B1: AppointmentID | C1: DoctorID | D1: Department | E1: Date | F1: Time | G1: Status
A2: P96099 | B2: N/A | C2: D26 | D2: Cardiology | E2: 45292 | F2: N/A | G2: N/A
A3: P16262 | B3: A7515 | C3: D1 | D3: Orthopedics | E3: 45545 | F3: 0.54166667 | G3: No Show
A4: P99601 | B4: A7537 | C4: D30 | D4: General Medicine | E4: 45643 | F4: 0.625 | G4: Completed
A5: P55235 | B5: A8866 | C5: D30 | D5: Neurology | E5: 45482 | F5: 0.64583333 | G5: Rescheduled
A6: P93372 | B6: A3039 | C6: D23 | D6: Pediatric | E6: 45516 | F6: 0.75 | G6: Cancelled
A7: P84444 | B7: A3237 | C7: D1 | D7: Pediatric | E7: 45357 | F7: 0.72916667 | G7: Rescheduled
A8: P41013 | B8: A8127 | C8: D24 | D8: Neurology | E8: 45383 | F8: 0.45833333 | G8: No Show
A9: P17235 | B9: A7025 | C9: D10 | D9: Neurology | E9: 45581 | F9: 0.625 | G9: No Show
A10: P35768 | B10: A8462 | C10: D8 | D10: Cardiology | E10: 45558 | F10: 0.64583333 | G10: Completed
A11: P28832 | B11: A9018 | C11: D14 | D11: Orthopedics | E11: 45395 | F11: 0.5625 | G11: Rescheduled
A12: P29680 | B12: A7791 | C12: D28 | D12: Orthopedics | E12: 45460 | F12: 0.35416667 | G12: No Show
A13: P93978 | B13: A4362 | C13: D5 | D13: Orthopedics | E13: 45519 | F13: 0.64583333 | G13: No Show
A14: P83760 | B14: N/A | C14: D1 | D14: Pediatric | E14: 45305 | F14: N/A | G14: Cancelled
A15: P41254 | B15: A1132 | C15: D23 | D15: Cardiology | E15: 45344 | F15: 0.33333333 | G15: Completed
A16: P73818 | B16: A6499 | C16: D6 | D16: Orthopedics | E16: 45311 | F16: 0.75 | G16: Rescheduled
A17: P79312 | B17: A2196 | C17: D14 | D17: Neurology | E17: 45589 | F17: 0.625 | G17: Completed
A18: P82827 | B18: A7135 | C18: D23 | D18: Neurology | E18: 45615 | F18: 0.60416667 | G18: Completed
A19: P25878 | B19: A8788 | C19: D28 | D19: Pediatric | E19: 45521 | F19: 0.66666667 | G19: Cancelled
A20: P93291 | B20: A1284 | C20: D6 | D20: Neurology | E20: 45476 | F20: 0.75 | G20: Rescheduled
A21: P14299 | B21: A7527 | C21: D29 | D21: Cardiology | E21: 45652 | F21: 0.52083333 | G21: Cancelled
A22: P90461 | B22: A5514 | C22: D15 | D22: Oncology | E22: 45640 | F22: 0.54166667 | G22: Cancelled
A23: P77174 | B23: A4853 | C23: D11 | D23: Pediatric | E23: 45635 | F23: 0.39583333 | G23: Rescheduled
A24: P38694 | B24: A4504 | C24: D14 | D24: General Medicine | E24: 45644 | F24: 0.41666667 | G24: No Show
A25: P45916 | B25: A2106 | C25: D25 | D25: General Medicine | E25: 45641 | F25: 0.75 | G25: Rescheduled
A26: P98707 | B26: N/A | C26: D20 | D26: General Medicine | E26: N/A | F26: 0.54166667 | G26: N/A
A27: P68619 | B27: A6156 | C27: D11 | D27: Pediatric | E27: 45558 | F27: 0.75 | G27: Completed
A28: P11071 | B28: A2963 | C28: D13 | D28: Orthopedics | E28: 45486 | F28: 0.77083333 | G28: Cancelled
A29: P18878 | B29: A1511 | C29: D27 | D29: Pediatric | E29: 45322 | F29: 0.75 | G29: No Show
A30: P88817 | B30: A1949 | C30: D28 | D30: Pediatric | E30: 45520 | F30: 0.66666667 | G30: Cancelled
A31: P70452 | B31: A9088 | C31: D7 | D31: Neurology | E31: 45622 | F31: 0.41666667 | G31: No Show
A32: P79213 | B32: A1384 | C32: D13 | D32: General Medicine | E32: 45642 | F32: 0.35416667 | G32: Rescheduled
A33: P92292 | B33: A4140 | C33: D17 | D33: Orthopedics | E33: 45384 | F33: 0.72916667 | G33: No Show
A34: P46858 | B34: A6170 | C34: D17 | D34: Oncology | E34: 45446 | F34: 0.64583333 | G34: Rescheduled
A35: P10337 | B35: A5704 | C35: D12 | D35: Neurology | E35: 45383 | F35: 0.41666667 | G35: Cancelled
A36: P76416 | B36: A1762 | C36: D26 | D36: Oncology | E36: 45646 | F36: 0.5625 | G36: No Show
A37: P47558 | B37: A3377 | C37: D30 | D37: Orthopedics | E37: 45647 | F37: 0.6875 | G37: No Show
A38: P10851 | B38: A7484 | C38: D11 | D38: General Medicine | E38: 45416 | F38: 0.6875 | G38: Completed
... A55: P40896 | B55: A7514 | C55: D4 | D55: Cardiology | E55: 45362 | F55: 0.64583333 | G55: Cancelled
A56: P86378 | B56: N/A | C56: D19 | D56: Neurology | E56: N/A | F56: N/A | G56: N/A
...

Sheet resource_data
A1: ResourceID | B1: Department | C1: ResourceType | D1: UsageHours | E1: Date | F1: Availability
A2: R5487 | B2: Cardiology | C2: Nurse | D2: 2 | E2: 45501 | F2: Unavailable
A3: R8097 | B3: Orthopedics | C3: Doctor | D3: 9 | E3: 45545 | F3: Unavailable
A4: R2557 | B4: General Medicine | C4: Room | D4: 5 | E4: 45643 | F4: Under Maintenance
A5: R9024 | B5: Neurology | C5: Doctor | D5: 9 | E5: 45482 | F5: Unavailable
A6: R9181 | B6: N/A | C6: Room | D6: 0 | E6: N/A | F6: Available
A7: R2629 | B7: Oncology | C7: Doctor | D7: 4 | E7: 45357 | F7: Unavailable
A8: R1317 | B8: Cardiology | C8: Nurse | D8: 0 | E8: 45383 | F8: Available
A9: R9640 | B9: Neurology | C9: Room | D9: 1 | E9: 45581 | F9: Available
A10: R1787 | B10: Oncology | C10: Doctor | D10: 8 | E10: 45558 | F10: Available
A11: R9426 | B11: Cardiology | C11: Technician | D11: 5 | E11: 45395 | F11: Unavailable
A12: R1606 | B12: General Medicine | C12: Nurse | D12: 8 | E12: 45460 | F12: Available
A13: R3242 | B13: Pediatric | C13: Doctor | D13: 0 | E13: 45519 | F13: Available
A14: R6893 | B14: Neurology | C14: Doctor | D14: 3 | E14: 45416 | F14: Available
A15: R3237 | B15: Orthopedics | C15: Nurse | D15: 4 | E15: 45344 | F15: Available
A16: R5274 | B16: General Medicine | C16: Doctor | D16: 7 | E16: 45311 | F16: Unavailable
A17: R1039 | B17: Neurology | C17: Technician | D17: 5 | E17: 45589 | F17: Available
A18: R5597 | B18: Neurology | C18: Nurse | D18: 4 | E18: 45615 | F18: Unavailable
... A21: R5074 | B21: Oncology | C21: Room | D21: 4 | E21: 45652 | F21: In Use
A22: R3855 | B22: Orthopedics | C22: N/A | D22: 0 | E22: N/A | F22: Unavailable
A23: R8405 | B23: Neurology | C23: Technician | D23: 5 | E23: 45635 | F23: Available
A24: R5984 | B24: Orthopedics | C24: Equipment | D24: 3 | E24: 45644 | F24: In Use
A25: R6968 | B25: General Medicine | C25: Doctor | D25: 1 | E25: 45641 | F25: Unavailable
A26: R7116 | B26: Cardiology | C26: Technician | D26: 8 | E26: 45392 | F26: Available
A27: R4399 | B27: General Medicine | C27: Room | D27: 7 | E27: 45558 | F27: Under Maintenance
A28: R6261 | B28: Neurology | C28: Equipment | D28: 5 | E28: 45486 | F28: Under Maintenance
A29: R9923 | B29: Cardiology | C29: Technician | D29: 8 | E29: 45322 | F29: Available
A30: R6097 | B30: Neurology | C30: Nurse | D30: 9 | E30: 45520 | F30: Available
A31: R1624 | B31: Oncology | C31: Room | D31: 2 | E31: 45622 | F31: In Use
A32: R6385 | B32: Oncology | C32: Doctor | D32: 0 | E32: 45642 | F32: Unavailable
A33: R2625 | B33: Neurology | C33: Equipment | D33: 5 | E33: 45384 | F33: Under Maintenance
A34: R3097 | B34: Orthopedics | C34: Room | D34: 6 | E34: 45446 | F34: Under Maintenance
... A44: R2833 | B44: General Medicine | C44: Equipment | D44: 3 | E44: 45507 | F44: In Use
A45: N/A | B45: Oncology | C45: N/A | D45: 1 | E45: N/A | F45: Available
A46: R5799 | B46: General Medicine | C46: Nurse | D46: 9 | E46: 45313 | F46: Unavailable
A47: R2825 | B47: Pediatric | C47: Technician | D47: 8 | E47: 45347 | F47: Available
A48: R5252 | B48: Pediatric | C48: Nurse | D48: 7 | E48: 45466 | F48: Unavailable
A49: R7354 | B49: Pediatric | C49: Doctor | D49: 0 | E49: 45350 | F49: Available
A50: R2717 | B50: Cardiology | C50: Technician | D50: 3 | E50: 45590 | F50: Available
A51: R3782 | B51: Pediatric | C51: Doctor | D51: 7 | E51: 45324 | F51: Unavailable
...

Sheet Resource Allocation
A3: Row Labels | B3: Average of UsageHours
A4: Cardiology | B4: 4.4545455
A5: General Medicine | B5: 4.5128205
A6: N/A | B6: 1
A7: Neurology | B7: 4.2941176
A8: Oncology | B8: 3.8333333
A9: Orthopedics | B9: 4.4444444
A10: Pediatric | B10: 4.8
A11: Grand Total | B11: 4.36

Sheet Appointment Hours
A3: Count of AppointmentID | B3: Column Labels
A4: Row Labels | B4: Cardiology | C4: General Medicine | D4: N/A | E4: Neurology | F4: Oncology | G4: Orthopedics | H4: Pediatric | I4: Grand Total
A5: N/A | B5: 1 | C5: 1 | D5: 1 | E5: 1 | F5: 3 | H5: 2 | I5: 9
A6: 0.33333333 | B6: 4 | E6: 3 | F6: 1 | H6: 3 | I6: 11
A7: 0.35416667 | B7: 1 | C7: 3 | G7: 2 | H7: 1 | I7: 7
A8: 0.375 | B8: 1 | C8: 1 | E8: 1 | F8: 2 | G8: 1 | H8: 2 | I8: 8
A9: 0.39583333 | B9: 2 | C9: 1 | G9: 1 | H9: 3 | I9: 7
A10: 0.41666667 | C10: 2 | E10: 3 | F10: 1 | G10: 1 | H10: 3 | I10: 10
A11: 0.4375 | C11: 1 | E11: 1 | H11: 2 | I11: 4
A12: 0.45833333 | B12: 1 | C12: 2 | E12: 3 | F12: 1 | G12: 3 | H12: 1 | I12: 11
A13: 0.47916667 | B13: 2 | E13: 1 | F13: 2 | H13: 1 | I13: 6
A14: 0.5 | B14: 4 | C14: 2 | E14: 4 | F14: 2 | I14: 12
A15: 0.52083333 | B15: 2 | E15: 2 | G15: 1 | H15: 1 | I15: 6
A16: 0.54166667 | B16: 2 | C16: 2 | F16: 1 | G16: 1 | H16: 1 | I16: 7
A17: 0.5625 | C17: 1 | F17: 1 | G17: 1 | H17: 2 | I17: 5
A18: 0.58333333 | B18: 1 | C18: 2 | G18: 2 | H18: 1 | I18: 6
A19: 0.60416667 | B19: 2 | E19: 2 | F19: 1 | H19: 2 | I19: 7
A20: 0.625 | B20: 1 | C20: 1 | E20: 2 | F20: 2 | G20: 3 | I20: 9
A21: 0.64583333 | B21: 4 | C21: 1 | E21: 2 | F21: 1 | G21: 2 | I21: 10
A22: 0.66666667 | B22: 1 | C22: 1 | E22: 1 | F22: 4 | G22: 1 | H22: 2 | I22: 10
A23: 0.6875 | B23: 1 | C23: 2 | E23: 1 | F23: 2 | G23: 1 | H23: 1 | I23: 8
A24: 0.70833333 | C24: 2 | E24: 2 | F24: 2 | G24: 3 | H24: 2 | I24: 11
A25: 0.72916667 | B25: 4 | F25: 1 | G25: 2 | H25: 2 | I25: 9
A26: 0.75 | B26: 1 | C26: 2 | E26: 2 | F26: 4 | G26: 2 | H26: 4 | I26: 15
A27: 0.77083333 | B27: 1 | C27: 1 | E27: 3 | F27: 2 | G27: 4 | H27: 1 | I27: 12
A28: Grand Total | B28: 36 | C28: 28 | D28: 1 | E28: 34 | F28: 33 | G28: 31 | H28: 37 | I28: 200

Sheet Satisfaction level
A3: Average of Feedback Score | B3: Column Labels
A4: Row Labels | B4: Cardiology | C4: General Medicine | D4: N/A | E4: Neurology | F4: Oncology | G4: Orthopedics | H4: Pediatric | I4: Grand Total
A5: High | B5: 7.2903226 | C5: 5.952381 | D5: 6.1014064 | E5: 6.3636364 | F5: 7.3076923 | G5: 7.1363636 | H5: 6.84375 | I5: 6.8006386
A6: Low | B6: 3 | C6: 3 | E6: 3 | F6: 3 | G6: 3 | H6: 3 | I6: 3
A7: Grand Total | B7: 7.030303 | C7: 5.3846154 | D7: 6.1014064 | E7: 6.2647059 | F7: 6.5 | G7: 6.0333333 | H7: 6.3243243 | I7: 6.2849741
